Defaulting to user installation because normal site-packages is not writeable
Collecting numpy
  Using cached numpy-1.21.6-pp37-pypy37_pp73-linux_aarch64.whl
Collecting selenium
  Using cached selenium-4.1.3-py3-none-any.whl (968 kB)
Collecting pyTelegramBotAPI
  Using cached pyTelegramBotAPI-4.4.0-py3-none-any.whl
Requirement already satisfied: urllib3[secure,socks]~=1.26 in /usr/lib/python3/dist-packages (from selenium) (1.26.5)
Collecting trio~=0.17
  Using cached trio-0.20.0-py3-none-any.whl (359 kB)
Collecting trio-websocket~=0.9
  Using cached trio_websocket-0.9.2-py3-none-any.whl (16 kB)
Requirement already satisfied: requests in /usr/lib/python3/dist-packages (from pyTelegramBotAPI) (2.25.1)
Collecting attrs>=19.2.0
  Using cached attrs-21.4.0-py2.py3-none-any.whl (60 kB)
Collecting sortedcontainers
  Using cached sortedcontainers-2.4.0-py2.py3-none-any.whl (29 kB)
Collecting async-generator>=1.9
  Using cached async_generator-1.10-py3-none-any.whl (18 kB)
Requirement already satisfied: idna in /usr/lib/python3/dist-packages (from trio~=0.17->selenium) (2.10)
Collecting outcome
  Using cached outcome-1.1.0-py2.py3-none-any.whl (9.7 kB)
Collecting sniffio
  Using cached sniffio-1.2.0-py3-none-any.whl (10 kB)
Collecting wsproto>=0.14
  Using cached wsproto-1.1.0-py3-none-any.whl (24 kB)
Requirement already satisfied: certifi in /usr/lib/python3/dist-packages (from urllib3[secure,socks]~=1.26->selenium) (2020.6.20)
Requirement already satisfied: cryptography>=1.3.4 in /usr/lib/python3/dist-packages (from urllib3[secure,socks]~=1.26->selenium) (3.3.2)
Collecting pyOpenSSL>=0.14
  Using cached pyOpenSSL-22.0.0-py2.py3-none-any.whl (55 kB)
Collecting PySocks!=1.5.7,<2.0,>=1.5.6
  Using cached PySocks-1.7.1-py3-none-any.whl (16 kB)
Collecting cryptography>=1.3.4
  Using cached cryptography-36.0.2.tar.gz (572 kB)
  Installing build dependencies: started
  Installing build dependencies: finished with status 'done'
  Getting requirements to build wheel: started
  Getting requirements to build wheel: finished with status 'done'
  Preparing metadata (pyproject.toml): started
  Preparing metadata (pyproject.toml): finished with status 'done'
Requirement already satisfied: cffi>=1.12 in /usr/lib/pypy3/lib_pypy (from cryptography>=1.3.4->urllib3[secure,socks]~=1.26->selenium) (1.14.5)
Collecting h11<1,>=0.9.0
  Using cached h11-0.13.0-py3-none-any.whl (58 kB)
Collecting typing-extensions
  Using cached typing_extensions-4.1.1-py3-none-any.whl (26 kB)
Building wheels for collected packages: cryptography
  Building wheel for cryptography (pyproject.toml): started
2022-04-16 04:40:34,540 (__init__.py:621 MainThread) ERROR - TeleBot: "Infinity polling exception: HTTPSConnectionPool(host='api.telegram.org', port=443): Read timed out. (read timeout=10)"
2022-04-16 04:40:34,547 (__init__.py:623 MainThread) ERROR - TeleBot: "Exception traceback:
Traceback (most recent call last):
  File "/usr/lib/python3/dist-packages/urllib3/connectionpool.py", line 445, in _make_request
    six.raise_from(e, None)
  File "<string>", line 3, in raise_from
  File "/usr/lib/python3/dist-packages/urllib3/connectionpool.py", line 440, in _make_request
    httplib_response = conn.getresponse()
  File "/usr/lib/pypy3/lib-python/3/http/client.py", line 1369, in getresponse
    response.begin()
  File "/usr/lib/pypy3/lib-python/3/http/client.py", line 310, in begin
    version, status, reason = self._read_status()
  File "/usr/lib/pypy3/lib-python/3/http/client.py", line 271, in _read_status
    line = str(self.fp.readline(_MAXLINE + 1), "iso-8859-1")
  File "/usr/lib/pypy3/lib-python/3/socket.py", line 589, in readinto
    return self._sock.recv_into(b)
  File "/usr/lib/pypy3/lib-python/3/ssl.py", line 1071, in recv_into
    return self.read(nbytes, buffer)
  File "/usr/lib/pypy3/lib-python/3/ssl.py", line 929, in read
    return self._sslobj.read(len, buffer)
  File "/usr/lib/pypy3/lib_pypy/_cffi_ssl/_stdssl/__init__.py", line 647, in read
    raise socket.timeout("The read operation timed out")
_socket.timeout: The read operation timed out

During handling of the above exception, another exception occurred:

Traceback (most recent call last):
  File "/usr/lib/python3/dist-packages/requests/adapters.py", line 449, in send
    timeout=timeout
  File "/usr/lib/python3/dist-packages/urllib3/connectionpool.py", line 756, in urlopen
    method, url, error=e, _pool=self, _stacktrace=sys.exc_info()[2]
  File "/usr/lib/python3/dist-packages/urllib3/util/retry.py", line 532, in increment
    raise six.reraise(type(error), error, _stacktrace)
  File "/usr/lib/python3/dist-packages/six.py", line 719, in reraise
    raise value
  File "/usr/lib/python3/dist-packages/urllib3/connectionpool.py", line 706, in urlopen
    chunked=chunked,
  File "/usr/lib/python3/dist-packages/urllib3/connectionpool.py", line 447, in _make_request
    self._raise_timeout(err=e, url=url, timeout_value=read_timeout)
  File "/usr/lib/python3/dist-packages/urllib3/connectionpool.py", line 337, in _raise_timeout
    self, url, "Read timed out. (read timeout=%s)" % timeout_value
urllib3.exceptions.ReadTimeoutError: HTTPSConnectionPool(host='api.telegram.org', port=443): Read timed out. (read timeout=10)

During handling of the above exception, another exception occurred:

Traceback (most recent call last):
  File "/home/vaskozlov/.local/lib/pypy3.7/site-packages/telebot/__init__.py", line 618, in infinity_polling
    allowed_updates=allowed_updates, *args, **kwargs)
  File "/home/vaskozlov/.local/lib/pypy3.7/site-packages/telebot/__init__.py", line 664, in polling
    self.__threaded_polling(non_stop, interval, timeout, long_polling_timeout, allowed_updates)
  File "/home/vaskozlov/.local/lib/pypy3.7/site-packages/telebot/__init__.py", line 726, in __threaded_polling
    raise e
  File "/home/vaskozlov/.local/lib/pypy3.7/site-packages/telebot/__init__.py", line 685, in __threaded_polling
    polling_thread.raise_exceptions()
  File "/home/vaskozlov/.local/lib/pypy3.7/site-packages/telebot/util.py", line 106, in raise_exceptions
    raise self.exception_info
  File "/home/vaskozlov/.local/lib/pypy3.7/site-packages/telebot/util.py", line 88, in run
    task(*args, **kwargs)
  File "/home/vaskozlov/.local/lib/pypy3.7/site-packages/telebot/__init__.py", line 413, in __retrieve_updates
    timeout=timeout, long_polling_timeout=long_polling_timeout)
  File "/home/vaskozlov/.local/lib/pypy3.7/site-packages/telebot/__init__.py", line 391, in get_updates
    json_updates = apihelper.get_updates(self.token, offset, limit, timeout, allowed_updates, long_polling_timeout)
  File "/home/vaskozlov/.local/lib/pypy3.7/site-packages/telebot/apihelper.py", line 328, in get_updates
    return _make_request(token, method_url, params=payload)
  File "/home/vaskozlov/.local/lib/pypy3.7/site-packages/telebot/apihelper.py", line 154, in _make_request
    timeout=(connect_timeout, read_timeout), proxies=proxy)
  File "/usr/lib/python3/dist-packages/requests/sessions.py", line 542, in request
    resp = self.send(prep, **send_kwargs)
  File "/usr/lib/python3/dist-packages/requests/sessions.py", line 655, in send
    r = adapter.send(request, **kwargs)
  File "/usr/lib/python3/dist-packages/requests/adapters.py", line 529, in send
    raise ReadTimeout(e, request=request)
requests.exceptions.ReadTimeout: HTTPSConnectionPool(host='api.telegram.org', port=443): Read timed out. (read timeout=10)
"
2022-04-16 04:40:57,609 (__init__.py:621 MainThread) ERROR - TeleBot: "Infinity polling exception: HTTPSConnectionPool(host='api.telegram.org', port=443): Max retries exceeded with url: /bot1463835745:AAEsUMnybJNU5GFzXr_FAqRz7lY6qyEg4Mg/getUpdates?offset=914101550&timeout=5 (Caused by NewConnectionError('<urllib3.connection.HTTPSConnection object at 0x0000ffffa88072b8>: Failed to establish a new connection: [Errno -3] Temporary failure in name resolution'))"
2022-04-16 04:40:57,614 (__init__.py:623 MainThread) ERROR - TeleBot: "Exception traceback:
Traceback (most recent call last):
  File "/usr/lib/python3/dist-packages/urllib3/connection.py", line 170, in _new_conn
    (self._dns_host, self.port), self.timeout, **extra_kw
  File "/usr/lib/python3/dist-packages/urllib3/util/connection.py", line 73, in create_connection
    for res in socket.getaddrinfo(host, port, family, socket.SOCK_STREAM):
  File "/usr/lib/pypy3/lib-python/3/socket.py", line 752, in getaddrinfo
    for res in _socket.getaddrinfo(host, port, family, type, proto, flags):
_socket.gaierror: [Errno -3] Temporary failure in name resolution

During handling of the above exception, another exception occurred:

Traceback (most recent call last):
  File "/usr/lib/python3/dist-packages/urllib3/connectionpool.py", line 706, in urlopen
    chunked=chunked,
  File "/usr/lib/python3/dist-packages/urllib3/connectionpool.py", line 382, in _make_request
    self._validate_conn(conn)
  File "/usr/lib/python3/dist-packages/urllib3/connectionpool.py", line 1012, in _validate_conn
    conn.connect()
  File "/usr/lib/python3/dist-packages/urllib3/connection.py", line 353, in connect
    conn = self._new_conn()
  File "/usr/lib/python3/dist-packages/urllib3/connection.py", line 182, in _new_conn
    self, "Failed to establish a new connection: %s" % e
urllib3.exceptions.NewConnectionError: <urllib3.connection.HTTPSConnection object at 0x0000ffffa88072b8>: Failed to establish a new connection: [Errno -3] Temporary failure in name resolution

During handling of the above exception, another exception occurred:

Traceback (most recent call last):
  File "/usr/lib/python3/dist-packages/requests/adapters.py", line 449, in send
    timeout=timeout
  File "/usr/lib/python3/dist-packages/urllib3/connectionpool.py", line 756, in urlopen
    method, url, error=e, _pool=self, _stacktrace=sys.exc_info()[2]
  File "/usr/lib/python3/dist-packages/urllib3/util/retry.py", line 574, in increment
    raise MaxRetryError(_pool, url, error or ResponseError(cause))
urllib3.exceptions.MaxRetryError: HTTPSConnectionPool(host='api.telegram.org', port=443): Max retries exceeded with url: /bot1463835745:AAEsUMnybJNU5GFzXr_FAqRz7lY6qyEg4Mg/getUpdates?offset=914101550&timeout=5 (Caused by NewConnectionError('<urllib3.connection.HTTPSConnection object at 0x0000ffffa88072b8>: Failed to establish a new connection: [Errno -3] Temporary failure in name resolution'))

During handling of the above exception, another exception occurred:

Traceback (most recent call last):
  File "/home/vaskozlov/.local/lib/pypy3.7/site-packages/telebot/__init__.py", line 618, in infinity_polling
    allowed_updates=allowed_updates, *args, **kwargs)
  File "/home/vaskozlov/.local/lib/pypy3.7/site-packages/telebot/__init__.py", line 664, in polling
    self.__threaded_polling(non_stop, interval, timeout, long_polling_timeout, allowed_updates)
  File "/home/vaskozlov/.local/lib/pypy3.7/site-packages/telebot/__init__.py", line 726, in __threaded_polling
    raise e
  File "/home/vaskozlov/.local/lib/pypy3.7/site-packages/telebot/__init__.py", line 685, in __threaded_polling
    polling_thread.raise_exceptions()
  File "/home/vaskozlov/.local/lib/pypy3.7/site-packages/telebot/util.py", line 106, in raise_exceptions
    raise self.exception_info
  File "/home/vaskozlov/.local/lib/pypy3.7/site-packages/telebot/util.py", line 88, in run
    task(*args, **kwargs)
  File "/home/vaskozlov/.local/lib/pypy3.7/site-packages/telebot/__init__.py", line 413, in __retrieve_updates
    timeout=timeout, long_polling_timeout=long_polling_timeout)
  File "/home/vaskozlov/.local/lib/pypy3.7/site-packages/telebot/__init__.py", line 391, in get_updates
    json_updates = apihelper.get_updates(self.token, offset, limit, timeout, allowed_updates, long_polling_timeout)
  File "/home/vaskozlov/.local/lib/pypy3.7/site-packages/telebot/apihelper.py", line 328, in get_updates
    return _make_request(token, method_url, params=payload)
  File "/home/vaskozlov/.local/lib/pypy3.7/site-packages/telebot/apihelper.py", line 154, in _make_request
    timeout=(connect_timeout, read_timeout), proxies=proxy)
  File "/usr/lib/python3/dist-packages/requests/sessions.py", line 542, in request
    resp = self.send(prep, **send_kwargs)
  File "/usr/lib/python3/dist-packages/requests/sessions.py", line 655, in send
    r = adapter.send(request, **kwargs)
  File "/usr/lib/python3/dist-packages/requests/adapters.py", line 516, in send
    raise ConnectionError(e, request=request)
requests.exceptions.ConnectionError: HTTPSConnectionPool(host='api.telegram.org', port=443): Max retries exceeded with url: /bot1463835745:AAEsUMnybJNU5GFzXr_FAqRz7lY6qyEg4Mg/getUpdates?offset=914101550&timeout=5 (Caused by NewConnectionError('<urllib3.connection.HTTPSConnection object at 0x0000ffffa88072b8>: Failed to establish a new connection: [Errno -3] Temporary failure in name resolution'))
"
2022-04-16 04:41:17,918 (__init__.py:621 MainThread) ERROR - TeleBot: "Infinity polling exception: HTTPSConnectionPool(host='api.telegram.org', port=443): Max retries exceeded with url: /bot1463835745:AAEsUMnybJNU5GFzXr_FAqRz7lY6qyEg4Mg/getUpdates?offset=914101550&timeout=5 (Caused by NewConnectionError('<urllib3.connection.HTTPSConnection object at 0x0000ffff8df14800>: Failed to establish a new connection: [Errno -3] Temporary failure in name resolution'))"
2022-04-16 04:41:17,923 (__init__.py:623 MainThread) ERROR - TeleBot: "Exception traceback:
Traceback (most recent call last):
  File "/usr/lib/python3/dist-packages/urllib3/connection.py", line 170, in _new_conn
    (self._dns_host, self.port), self.timeout, **extra_kw
  File "/usr/lib/python3/dist-packages/urllib3/util/connection.py", line 73, in create_connection
    for res in socket.getaddrinfo(host, port, family, socket.SOCK_STREAM):
  File "/usr/lib/pypy3/lib-python/3/socket.py", line 752, in getaddrinfo
    for res in _socket.getaddrinfo(host, port, family, type, proto, flags):
_socket.gaierror: [Errno -3] Temporary failure in name resolution

During handling of the above exception, another exception occurred:

Traceback (most recent call last):
  File "/usr/lib/python3/dist-packages/urllib3/connectionpool.py", line 706, in urlopen
    chunked=chunked,
  File "/usr/lib/python3/dist-packages/urllib3/connectionpool.py", line 382, in _make_request
    self._validate_conn(conn)
  File "/usr/lib/python3/dist-packages/urllib3/connectionpool.py", line 1012, in _validate_conn
    conn.connect()
  File "/usr/lib/python3/dist-packages/urllib3/connection.py", line 353, in connect
    conn = self._new_conn()
  File "/usr/lib/python3/dist-packages/urllib3/connection.py", line 182, in _new_conn
    self, "Failed to establish a new connection: %s" % e
urllib3.exceptions.NewConnectionError: <urllib3.connection.HTTPSConnection object at 0x0000ffff8df14800>: Failed to establish a new connection: [Errno -3] Temporary failure in name resolution

During handling of the above exception, another exception occurred:

Traceback (most recent call last):
  File "/usr/lib/python3/dist-packages/requests/adapters.py", line 449, in send
    timeout=timeout
  File "/usr/lib/python3/dist-packages/urllib3/connectionpool.py", line 756, in urlopen
    method, url, error=e, _pool=self, _stacktrace=sys.exc_info()[2]
  File "/usr/lib/python3/dist-packages/urllib3/util/retry.py", line 574, in increment
    raise MaxRetryError(_pool, url, error or ResponseError(cause))
urllib3.exceptions.MaxRetryError: HTTPSConnectionPool(host='api.telegram.org', port=443): Max retries exceeded with url: /bot1463835745:AAEsUMnybJNU5GFzXr_FAqRz7lY6qyEg4Mg/getUpdates?offset=914101550&timeout=5 (Caused by NewConnectionError('<urllib3.connection.HTTPSConnection object at 0x0000ffff8df14800>: Failed to establish a new connection: [Errno -3] Temporary failure in name resolution'))

During handling of the above exception, another exception occurred:

Traceback (most recent call last):
  File "/home/vaskozlov/.local/lib/pypy3.7/site-packages/telebot/__init__.py", line 618, in infinity_polling
    allowed_updates=allowed_updates, *args, **kwargs)
  File "/home/vaskozlov/.local/lib/pypy3.7/site-packages/telebot/__init__.py", line 664, in polling
    self.__threaded_polling(non_stop, interval, timeout, long_polling_timeout, allowed_updates)
  File "/home/vaskozlov/.local/lib/pypy3.7/site-packages/telebot/__init__.py", line 726, in __threaded_polling
    raise e
  File "/home/vaskozlov/.local/lib/pypy3.7/site-packages/telebot/__init__.py", line 685, in __threaded_polling
    polling_thread.raise_exceptions()
  File "/home/vaskozlov/.local/lib/pypy3.7/site-packages/telebot/util.py", line 106, in raise_exceptions
    raise self.exception_info
  File "/home/vaskozlov/.local/lib/pypy3.7/site-packages/telebot/util.py", line 88, in run
    task(*args, **kwargs)
  File "/home/vaskozlov/.local/lib/pypy3.7/site-packages/telebot/__init__.py", line 413, in __retrieve_updates
    timeout=timeout, long_polling_timeout=long_polling_timeout)
  File "/home/vaskozlov/.local/lib/pypy3.7/site-packages/telebot/__init__.py", line 391, in get_updates
    json_updates = apihelper.get_updates(self.token, offset, limit, timeout, allowed_updates, long_polling_timeout)
  File "/home/vaskozlov/.local/lib/pypy3.7/site-packages/telebot/apihelper.py", line 328, in get_updates
    return _make_request(token, method_url, params=payload)
  File "/home/vaskozlov/.local/lib/pypy3.7/site-packages/telebot/apihelper.py", line 154, in _make_request
    timeout=(connect_timeout, read_timeout), proxies=proxy)
  File "/usr/lib/python3/dist-packages/requests/sessions.py", line 542, in request
    resp = self.send(prep, **send_kwargs)
  File "/usr/lib/python3/dist-packages/requests/sessions.py", line 655, in send
    r = adapter.send(request, **kwargs)
  File "/usr/lib/python3/dist-packages/requests/adapters.py", line 516, in send
    raise ConnectionError(e, request=request)
requests.exceptions.ConnectionError: HTTPSConnectionPool(host='api.telegram.org', port=443): Max retries exceeded with url: /bot1463835745:AAEsUMnybJNU5GFzXr_FAqRz7lY6qyEg4Mg/getUpdates?offset=914101550&timeout=5 (Caused by NewConnectionError('<urllib3.connection.HTTPSConnection object at 0x0000ffff8df14800>: Failed to establish a new connection: [Errno -3] Temporary failure in name resolution'))
"
2022-04-16 04:41:33,247 (__init__.py:621 MainThread) ERROR - TeleBot: "Infinity polling exception: HTTPSConnectionPool(host='api.telegram.org', port=443): Max retries exceeded with url: /bot1463835745:AAEsUMnybJNU5GFzXr_FAqRz7lY6qyEg4Mg/getUpdates?offset=914101550&timeout=5 (Caused by NewConnectionError('<urllib3.connection.HTTPSConnection object at 0x0000ffffab3746b0>: Failed to establish a new connection: [Errno -3] Temporary failure in name resolution'))"
2022-04-16 04:41:33,252 (__init__.py:623 MainThread) ERROR - TeleBot: "Exception traceback:
Traceback (most recent call last):
  File "/usr/lib/python3/dist-packages/urllib3/connection.py", line 170, in _new_conn
    (self._dns_host, self.port), self.timeout, **extra_kw
  File "/usr/lib/python3/dist-packages/urllib3/util/connection.py", line 73, in create_connection
    for res in socket.getaddrinfo(host, port, family, socket.SOCK_STREAM):
  File "/usr/lib/pypy3/lib-python/3/socket.py", line 752, in getaddrinfo
    for res in _socket.getaddrinfo(host, port, family, type, proto, flags):
_socket.gaierror: [Errno -3] Temporary failure in name resolution

During handling of the above exception, another exception occurred:

Traceback (most recent call last):
  File "/usr/lib/python3/dist-packages/urllib3/connectionpool.py", line 706, in urlopen
    chunked=chunked,
  File "/usr/lib/python3/dist-packages/urllib3/connectionpool.py", line 382, in _make_request
    self._validate_conn(conn)
  File "/usr/lib/python3/dist-packages/urllib3/connectionpool.py", line 1012, in _validate_conn
    conn.connect()
  File "/usr/lib/python3/dist-packages/urllib3/connection.py", line 353, in connect
    conn = self._new_conn()
  File "/usr/lib/python3/dist-packages/urllib3/connection.py", line 182, in _new_conn
    self, "Failed to establish a new connection: %s" % e
urllib3.exceptions.NewConnectionError: <urllib3.connection.HTTPSConnection object at 0x0000ffffab3746b0>: Failed to establish a new connection: [Errno -3] Temporary failure in name resolution

During handling of the above exception, another exception occurred:

Traceback (most recent call last):
  File "/usr/lib/python3/dist-packages/requests/adapters.py", line 449, in send
    timeout=timeout
  File "/usr/lib/python3/dist-packages/urllib3/connectionpool.py", line 756, in urlopen
    method, url, error=e, _pool=self, _stacktrace=sys.exc_info()[2]
  File "/usr/lib/python3/dist-packages/urllib3/util/retry.py", line 574, in increment
    raise MaxRetryError(_pool, url, error or ResponseError(cause))
urllib3.exceptions.MaxRetryError: HTTPSConnectionPool(host='api.telegram.org', port=443): Max retries exceeded with url: /bot1463835745:AAEsUMnybJNU5GFzXr_FAqRz7lY6qyEg4Mg/getUpdates?offset=914101550&timeout=5 (Caused by NewConnectionError('<urllib3.connection.HTTPSConnection object at 0x0000ffffab3746b0>: Failed to establish a new connection: [Errno -3] Temporary failure in name resolution'))

During handling of the above exception, another exception occurred:

Traceback (most recent call last):
  File "/home/vaskozlov/.local/lib/pypy3.7/site-packages/telebot/__init__.py", line 618, in infinity_polling
    allowed_updates=allowed_updates, *args, **kwargs)
  File "/home/vaskozlov/.local/lib/pypy3.7/site-packages/telebot/__init__.py", line 664, in polling
    self.__threaded_polling(non_stop, interval, timeout, long_polling_timeout, allowed_updates)
  File "/home/vaskozlov/.local/lib/pypy3.7/site-packages/telebot/__init__.py", line 726, in __threaded_polling
    raise e
  File "/home/vaskozlov/.local/lib/pypy3.7/site-packages/telebot/__init__.py", line 685, in __threaded_polling
    polling_thread.raise_exceptions()
  File "/home/vaskozlov/.local/lib/pypy3.7/site-packages/telebot/util.py", line 106, in raise_exceptions
    raise self.exception_info
  File "/home/vaskozlov/.local/lib/pypy3.7/site-packages/telebot/util.py", line 88, in run
    task(*args, **kwargs)
  File "/home/vaskozlov/.local/lib/pypy3.7/site-packages/telebot/__init__.py", line 413, in __retrieve_updates
    timeout=timeout, long_polling_timeout=long_polling_timeout)
  File "/home/vaskozlov/.local/lib/pypy3.7/site-packages/telebot/__init__.py", line 391, in get_updates
    json_updates = apihelper.get_updates(self.token, offset, limit, timeout, allowed_updates, long_polling_timeout)
  File "/home/vaskozlov/.local/lib/pypy3.7/site-packages/telebot/apihelper.py", line 328, in get_updates
    return _make_request(token, method_url, params=payload)
  File "/home/vaskozlov/.local/lib/pypy3.7/site-packages/telebot/apihelper.py", line 154, in _make_request
    timeout=(connect_timeout, read_timeout), proxies=proxy)
  File "/usr/lib/python3/dist-packages/requests/sessions.py", line 542, in request
    resp = self.send(prep, **send_kwargs)
  File "/usr/lib/python3/dist-packages/requests/sessions.py", line 655, in send
    r = adapter.send(request, **kwargs)
  File "/usr/lib/python3/dist-packages/requests/adapters.py", line 516, in send
    raise ConnectionError(e, request=request)
requests.exceptions.ConnectionError: HTTPSConnectionPool(host='api.telegram.org', port=443): Max retries exceeded with url: /bot1463835745:AAEsUMnybJNU5GFzXr_FAqRz7lY6qyEg4Mg/getUpdates?offset=914101550&timeout=5 (Caused by NewConnectionError('<urllib3.connection.HTTPSConnection object at 0x0000ffffab3746b0>: Failed to establish a new connection: [Errno -3] Temporary failure in name resolution'))
"
2022-04-16 04:41:37,342 (__init__.py:621 MainThread) ERROR - TeleBot: "Infinity polling exception: HTTPSConnectionPool(host='api.telegram.org', port=443): Max retries exceeded with url: /bot1463835745:AAEsUMnybJNU5GFzXr_FAqRz7lY6qyEg4Mg/getUpdates?offset=914101550&timeout=5 (Caused by NewConnectionError('<urllib3.connection.HTTPSConnection object at 0x0000ffffab71a9c0>: Failed to establish a new connection: [Errno -3] Temporary failure in name resolution'))"
2022-04-16 04:41:37,348 (__init__.py:623 MainThread) ERROR - TeleBot: "Exception traceback:
Traceback (most recent call last):
  File "/usr/lib/python3/dist-packages/urllib3/connection.py", line 170, in _new_conn
    (self._dns_host, self.port), self.timeout, **extra_kw
  File "/usr/lib/python3/dist-packages/urllib3/util/connection.py", line 73, in create_connection
    for res in socket.getaddrinfo(host, port, family, socket.SOCK_STREAM):
  File "/usr/lib/pypy3/lib-python/3/socket.py", line 752, in getaddrinfo
    for res in _socket.getaddrinfo(host, port, family, type, proto, flags):
_socket.gaierror: [Errno -3] Temporary failure in name resolution

During handling of the above exception, another exception occurred:

Traceback (most recent call last):
  File "/usr/lib/python3/dist-packages/urllib3/connectionpool.py", line 706, in urlopen
    chunked=chunked,
  File "/usr/lib/python3/dist-packages/urllib3/connectionpool.py", line 382, in _make_request
    self._validate_conn(conn)
  File "/usr/lib/python3/dist-packages/urllib3/connectionpool.py", line 1012, in _validate_conn
    conn.connect()
  File "/usr/lib/python3/dist-packages/urllib3/connection.py", line 353, in connect
    conn = self._new_conn()
  File "/usr/lib/python3/dist-packages/urllib3/connection.py", line 182, in _new_conn
    self, "Failed to establish a new connection: %s" % e
urllib3.exceptions.NewConnectionError: <urllib3.connection.HTTPSConnection object at 0x0000ffffab71a9c0>: Failed to establish a new connection: [Errno -3] Temporary failure in name resolution

During handling of the above exception, another exception occurred:

Traceback (most recent call last):
  File "/usr/lib/python3/dist-packages/requests/adapters.py", line 449, in send
    timeout=timeout
  File "/usr/lib/python3/dist-packages/urllib3/connectionpool.py", line 756, in urlopen
    method, url, error=e, _pool=self, _stacktrace=sys.exc_info()[2]
  File "/usr/lib/python3/dist-packages/urllib3/util/retry.py", line 574, in increment
    raise MaxRetryError(_pool, url, error or ResponseError(cause))
urllib3.exceptions.MaxRetryError: HTTPSConnectionPool(host='api.telegram.org', port=443): Max retries exceeded with url: /bot1463835745:AAEsUMnybJNU5GFzXr_FAqRz7lY6qyEg4Mg/getUpdates?offset=914101550&timeout=5 (Caused by NewConnectionError('<urllib3.connection.HTTPSConnection object at 0x0000ffffab71a9c0>: Failed to establish a new connection: [Errno -3] Temporary failure in name resolution'))

During handling of the above exception, another exception occurred:

Traceback (most recent call last):
  File "/home/vaskozlov/.local/lib/pypy3.7/site-packages/telebot/__init__.py", line 618, in infinity_polling
    allowed_updates=allowed_updates, *args, **kwargs)
  File "/home/vaskozlov/.local/lib/pypy3.7/site-packages/telebot/__init__.py", line 664, in polling
    self.__threaded_polling(non_stop, interval, timeout, long_polling_timeout, allowed_updates)
  File "/home/vaskozlov/.local/lib/pypy3.7/site-packages/telebot/__init__.py", line 726, in __threaded_polling
    raise e
  File "/home/vaskozlov/.local/lib/pypy3.7/site-packages/telebot/__init__.py", line 685, in __threaded_polling
    polling_thread.raise_exceptions()
  File "/home/vaskozlov/.local/lib/pypy3.7/site-packages/telebot/util.py", line 106, in raise_exceptions
    raise self.exception_info
  File "/home/vaskozlov/.local/lib/pypy3.7/site-packages/telebot/util.py", line 88, in run
    task(*args, **kwargs)
  File "/home/vaskozlov/.local/lib/pypy3.7/site-packages/telebot/__init__.py", line 413, in __retrieve_updates
    timeout=timeout, long_polling_timeout=long_polling_timeout)
  File "/home/vaskozlov/.local/lib/pypy3.7/site-packages/telebot/__init__.py", line 391, in get_updates
    json_updates = apihelper.get_updates(self.token, offset, limit, timeout, allowed_updates, long_polling_timeout)
  File "/home/vaskozlov/.local/lib/pypy3.7/site-packages/telebot/apihelper.py", line 328, in get_updates
    return _make_request(token, method_url, params=payload)
  File "/home/vaskozlov/.local/lib/pypy3.7/site-packages/telebot/apihelper.py", line 154, in _make_request
    timeout=(connect_timeout, read_timeout), proxies=proxy)
  File "/usr/lib/python3/dist-packages/requests/sessions.py", line 542, in request
    resp = self.send(prep, **send_kwargs)
  File "/usr/lib/python3/dist-packages/requests/sessions.py", line 655, in send
    r = adapter.send(request, **kwargs)
  File "/usr/lib/python3/dist-packages/requests/adapters.py", line 516, in send
    raise ConnectionError(e, request=request)
requests.exceptions.ConnectionError: HTTPSConnectionPool(host='api.telegram.org', port=443): Max retries exceeded with url: /bot1463835745:AAEsUMnybJNU5GFzXr_FAqRz7lY6qyEg4Mg/getUpdates?offset=914101550&timeout=5 (Caused by NewConnectionError('<urllib3.connection.HTTPSConnection object at 0x0000ffffab71a9c0>: Failed to establish a new connection: [Errno -3] Temporary failure in name resolution'))
"
2022-04-16 13:04:53,668 (__init__.py:621 MainThread) ERROR - TeleBot: "Infinity polling exception: HTTPSConnectionPool(host='api.telegram.org', port=443): Read timed out. (read timeout=10)"
2022-04-16 13:04:53,671 (__init__.py:623 MainThread) ERROR - TeleBot: "Exception traceback:
Traceback (most recent call last):
  File "/usr/lib/python3/dist-packages/urllib3/connectionpool.py", line 445, in _make_request
    six.raise_from(e, None)
  File "<string>", line 3, in raise_from
  File "/usr/lib/python3/dist-packages/urllib3/connectionpool.py", line 440, in _make_request
    httplib_response = conn.getresponse()
  File "/usr/lib/python3.9/http/client.py", line 1371, in getresponse
    response.begin()
  File "/usr/lib/python3.9/http/client.py", line 319, in begin
    version, status, reason = self._read_status()
  File "/usr/lib/python3.9/http/client.py", line 280, in _read_status
    line = str(self.fp.readline(_MAXLINE + 1), "iso-8859-1")
  File "/usr/lib/python3.9/socket.py", line 704, in readinto
    return self._sock.recv_into(b)
  File "/usr/lib/python3.9/ssl.py", line 1241, in recv_into
    return self.read(nbytes, buffer)
  File "/usr/lib/python3.9/ssl.py", line 1099, in read
    return self._sslobj.read(len, buffer)
socket.timeout: The read operation timed out

During handling of the above exception, another exception occurred:

Traceback (most recent call last):
  File "/usr/lib/python3/dist-packages/requests/adapters.py", line 439, in send
    resp = conn.urlopen(
  File "/usr/lib/python3/dist-packages/urllib3/connectionpool.py", line 755, in urlopen
    retries = retries.increment(
  File "/usr/lib/python3/dist-packages/urllib3/util/retry.py", line 532, in increment
    raise six.reraise(type(error), error, _stacktrace)
  File "/usr/lib/python3/dist-packages/six.py", line 719, in reraise
    raise value
  File "/usr/lib/python3/dist-packages/urllib3/connectionpool.py", line 699, in urlopen
    httplib_response = self._make_request(
  File "/usr/lib/python3/dist-packages/urllib3/connectionpool.py", line 447, in _make_request
    self._raise_timeout(err=e, url=url, timeout_value=read_timeout)
  File "/usr/lib/python3/dist-packages/urllib3/connectionpool.py", line 336, in _raise_timeout
    raise ReadTimeoutError(
urllib3.exceptions.ReadTimeoutError: HTTPSConnectionPool(host='api.telegram.org', port=443): Read timed out. (read timeout=10)

During handling of the above exception, another exception occurred:

Traceback (most recent call last):
  File "/home/vaskozlov/.local/lib/python3.9/site-packages/telebot/__init__.py", line 617, in infinity_polling
    self.polling(none_stop=True, timeout=timeout, long_polling_timeout=long_polling_timeout,
  File "/home/vaskozlov/.local/lib/python3.9/site-packages/telebot/__init__.py", line 664, in polling
    self.__threaded_polling(non_stop, interval, timeout, long_polling_timeout, allowed_updates)
  File "/home/vaskozlov/.local/lib/python3.9/site-packages/telebot/__init__.py", line 726, in __threaded_polling
    raise e
  File "/home/vaskozlov/.local/lib/python3.9/site-packages/telebot/__init__.py", line 685, in __threaded_polling
    polling_thread.raise_exceptions()
  File "/home/vaskozlov/.local/lib/python3.9/site-packages/telebot/util.py", line 106, in raise_exceptions
    raise self.exception_info
  File "/home/vaskozlov/.local/lib/python3.9/site-packages/telebot/util.py", line 88, in run
    task(*args, **kwargs)
  File "/home/vaskozlov/.local/lib/python3.9/site-packages/telebot/__init__.py", line 411, in __retrieve_updates
    updates = self.get_updates(offset=(self.last_update_id + 1),
  File "/home/vaskozlov/.local/lib/python3.9/site-packages/telebot/__init__.py", line 391, in get_updates
    json_updates = apihelper.get_updates(self.token, offset, limit, timeout, allowed_updates, long_polling_timeout)
  File "/home/vaskozlov/.local/lib/python3.9/site-packages/telebot/apihelper.py", line 328, in get_updates
    return _make_request(token, method_url, params=payload)
  File "/home/vaskozlov/.local/lib/python3.9/site-packages/telebot/apihelper.py", line 152, in _make_request
    result = _get_req_session().request(
  File "/usr/lib/python3/dist-packages/requests/sessions.py", line 542, in request
    resp = self.send(prep, **send_kwargs)
  File "/usr/lib/python3/dist-packages/requests/sessions.py", line 655, in send
    r = adapter.send(request, **kwargs)
  File "/usr/lib/python3/dist-packages/requests/adapters.py", line 529, in send
    raise ReadTimeout(e, request=request)
requests.exceptions.ReadTimeout: HTTPSConnectionPool(host='api.telegram.org', port=443): Read timed out. (read timeout=10)
"
2022-04-16 13:05:30,866 (__init__.py:621 MainThread) ERROR - TeleBot: "Infinity polling exception: HTTPSConnectionPool(host='api.telegram.org', port=443): Read timed out. (read timeout=10)"
2022-04-16 13:05:30,869 (__init__.py:623 MainThread) ERROR - TeleBot: "Exception traceback:
Traceback (most recent call last):
  File "/usr/lib/python3/dist-packages/urllib3/connectionpool.py", line 445, in _make_request
    six.raise_from(e, None)
  File "<string>", line 3, in raise_from
  File "/usr/lib/python3/dist-packages/urllib3/connectionpool.py", line 440, in _make_request
    httplib_response = conn.getresponse()
  File "/usr/lib/python3.9/http/client.py", line 1371, in getresponse
    response.begin()
  File "/usr/lib/python3.9/http/client.py", line 319, in begin
    version, status, reason = self._read_status()
  File "/usr/lib/python3.9/http/client.py", line 280, in _read_status
    line = str(self.fp.readline(_MAXLINE + 1), "iso-8859-1")
  File "/usr/lib/python3.9/socket.py", line 704, in readinto
    return self._sock.recv_into(b)
  File "/usr/lib/python3.9/ssl.py", line 1241, in recv_into
    return self.read(nbytes, buffer)
  File "/usr/lib/python3.9/ssl.py", line 1099, in read
    return self._sslobj.read(len, buffer)
socket.timeout: The read operation timed out

During handling of the above exception, another exception occurred:

Traceback (most recent call last):
  File "/usr/lib/python3/dist-packages/requests/adapters.py", line 439, in send
    resp = conn.urlopen(
  File "/usr/lib/python3/dist-packages/urllib3/connectionpool.py", line 755, in urlopen
    retries = retries.increment(
  File "/usr/lib/python3/dist-packages/urllib3/util/retry.py", line 532, in increment
    raise six.reraise(type(error), error, _stacktrace)
  File "/usr/lib/python3/dist-packages/six.py", line 719, in reraise
    raise value
  File "/usr/lib/python3/dist-packages/urllib3/connectionpool.py", line 699, in urlopen
    httplib_response = self._make_request(
  File "/usr/lib/python3/dist-packages/urllib3/connectionpool.py", line 447, in _make_request
    self._raise_timeout(err=e, url=url, timeout_value=read_timeout)
  File "/usr/lib/python3/dist-packages/urllib3/connectionpool.py", line 336, in _raise_timeout
    raise ReadTimeoutError(
urllib3.exceptions.ReadTimeoutError: HTTPSConnectionPool(host='api.telegram.org', port=443): Read timed out. (read timeout=10)

During handling of the above exception, another exception occurred:

Traceback (most recent call last):
  File "/home/vaskozlov/.local/lib/python3.9/site-packages/telebot/__init__.py", line 617, in infinity_polling
    self.polling(none_stop=True, timeout=timeout, long_polling_timeout=long_polling_timeout,
  File "/home/vaskozlov/.local/lib/python3.9/site-packages/telebot/__init__.py", line 664, in polling
    self.__threaded_polling(non_stop, interval, timeout, long_polling_timeout, allowed_updates)
  File "/home/vaskozlov/.local/lib/python3.9/site-packages/telebot/__init__.py", line 726, in __threaded_polling
    raise e
  File "/home/vaskozlov/.local/lib/python3.9/site-packages/telebot/__init__.py", line 685, in __threaded_polling
    polling_thread.raise_exceptions()
  File "/home/vaskozlov/.local/lib/python3.9/site-packages/telebot/util.py", line 106, in raise_exceptions
    raise self.exception_info
  File "/home/vaskozlov/.local/lib/python3.9/site-packages/telebot/util.py", line 88, in run
    task(*args, **kwargs)
  File "/home/vaskozlov/.local/lib/python3.9/site-packages/telebot/__init__.py", line 411, in __retrieve_updates
    updates = self.get_updates(offset=(self.last_update_id + 1),
  File "/home/vaskozlov/.local/lib/python3.9/site-packages/telebot/__init__.py", line 391, in get_updates
    json_updates = apihelper.get_updates(self.token, offset, limit, timeout, allowed_updates, long_polling_timeout)
  File "/home/vaskozlov/.local/lib/python3.9/site-packages/telebot/apihelper.py", line 328, in get_updates
    return _make_request(token, method_url, params=payload)
  File "/home/vaskozlov/.local/lib/python3.9/site-packages/telebot/apihelper.py", line 152, in _make_request
    result = _get_req_session().request(
  File "/usr/lib/python3/dist-packages/requests/sessions.py", line 542, in request
    resp = self.send(prep, **send_kwargs)
  File "/usr/lib/python3/dist-packages/requests/sessions.py", line 655, in send
    r = adapter.send(request, **kwargs)
  File "/usr/lib/python3/dist-packages/requests/adapters.py", line 529, in send
    raise ReadTimeout(e, request=request)
requests.exceptions.ReadTimeout: HTTPSConnectionPool(host='api.telegram.org', port=443): Read timed out. (read timeout=10)
"
2022-04-16 13:05:51,500 (__init__.py:621 MainThread) ERROR - TeleBot: "Infinity polling exception: HTTPSConnectionPool(host='api.telegram.org', port=443): Read timed out. (read timeout=10)"
2022-04-16 13:05:51,503 (__init__.py:623 MainThread) ERROR - TeleBot: "Exception traceback:
Traceback (most recent call last):
  File "/usr/lib/python3/dist-packages/urllib3/connectionpool.py", line 445, in _make_request
    six.raise_from(e, None)
  File "<string>", line 3, in raise_from
  File "/usr/lib/python3/dist-packages/urllib3/connectionpool.py", line 440, in _make_request
    httplib_response = conn.getresponse()
  File "/usr/lib/python3.9/http/client.py", line 1371, in getresponse
    response.begin()
  File "/usr/lib/python3.9/http/client.py", line 319, in begin
    version, status, reason = self._read_status()
  File "/usr/lib/python3.9/http/client.py", line 280, in _read_status
    line = str(self.fp.readline(_MAXLINE + 1), "iso-8859-1")
  File "/usr/lib/python3.9/socket.py", line 704, in readinto
    return self._sock.recv_into(b)
  File "/usr/lib/python3.9/ssl.py", line 1241, in recv_into
    return self.read(nbytes, buffer)
  File "/usr/lib/python3.9/ssl.py", line 1099, in read
    return self._sslobj.read(len, buffer)
socket.timeout: The read operation timed out

During handling of the above exception, another exception occurred:

Traceback (most recent call last):
  File "/usr/lib/python3/dist-packages/requests/adapters.py", line 439, in send
    resp = conn.urlopen(
  File "/usr/lib/python3/dist-packages/urllib3/connectionpool.py", line 755, in urlopen
    retries = retries.increment(
  File "/usr/lib/python3/dist-packages/urllib3/util/retry.py", line 532, in increment
    raise six.reraise(type(error), error, _stacktrace)
  File "/usr/lib/python3/dist-packages/six.py", line 719, in reraise
    raise value
  File "/usr/lib/python3/dist-packages/urllib3/connectionpool.py", line 699, in urlopen
    httplib_response = self._make_request(
  File "/usr/lib/python3/dist-packages/urllib3/connectionpool.py", line 447, in _make_request
    self._raise_timeout(err=e, url=url, timeout_value=read_timeout)
  File "/usr/lib/python3/dist-packages/urllib3/connectionpool.py", line 336, in _raise_timeout
    raise ReadTimeoutError(
urllib3.exceptions.ReadTimeoutError: HTTPSConnectionPool(host='api.telegram.org', port=443): Read timed out. (read timeout=10)

During handling of the above exception, another exception occurred:

Traceback (most recent call last):
  File "/home/vaskozlov/.local/lib/python3.9/site-packages/telebot/__init__.py", line 617, in infinity_polling
    self.polling(none_stop=True, timeout=timeout, long_polling_timeout=long_polling_timeout,
  File "/home/vaskozlov/.local/lib/python3.9/site-packages/telebot/__init__.py", line 664, in polling
    self.__threaded_polling(non_stop, interval, timeout, long_polling_timeout, allowed_updates)
  File "/home/vaskozlov/.local/lib/python3.9/site-packages/telebot/__init__.py", line 726, in __threaded_polling
    raise e
  File "/home/vaskozlov/.local/lib/python3.9/site-packages/telebot/__init__.py", line 685, in __threaded_polling
    polling_thread.raise_exceptions()
  File "/home/vaskozlov/.local/lib/python3.9/site-packages/telebot/util.py", line 106, in raise_exceptions
    raise self.exception_info
  File "/home/vaskozlov/.local/lib/python3.9/site-packages/telebot/util.py", line 88, in run
    task(*args, **kwargs)
  File "/home/vaskozlov/.local/lib/python3.9/site-packages/telebot/__init__.py", line 411, in __retrieve_updates
    updates = self.get_updates(offset=(self.last_update_id + 1),
  File "/home/vaskozlov/.local/lib/python3.9/site-packages/telebot/__init__.py", line 391, in get_updates
    json_updates = apihelper.get_updates(self.token, offset, limit, timeout, allowed_updates, long_polling_timeout)
  File "/home/vaskozlov/.local/lib/python3.9/site-packages/telebot/apihelper.py", line 328, in get_updates
    return _make_request(token, method_url, params=payload)
  File "/home/vaskozlov/.local/lib/python3.9/site-packages/telebot/apihelper.py", line 152, in _make_request
    result = _get_req_session().request(
  File "/usr/lib/python3/dist-packages/requests/sessions.py", line 542, in request
    resp = self.send(prep, **send_kwargs)
  File "/usr/lib/python3/dist-packages/requests/sessions.py", line 655, in send
    r = adapter.send(request, **kwargs)
  File "/usr/lib/python3/dist-packages/requests/adapters.py", line 529, in send
    raise ReadTimeout(e, request=request)
requests.exceptions.ReadTimeout: HTTPSConnectionPool(host='api.telegram.org', port=443): Read timed out. (read timeout=10)
"
2022-04-16 13:06:14,224 (__init__.py:621 MainThread) ERROR - TeleBot: "Infinity polling exception: HTTPSConnectionPool(host='api.telegram.org', port=443): Read timed out. (read timeout=10)"
2022-04-16 13:06:14,227 (__init__.py:623 MainThread) ERROR - TeleBot: "Exception traceback:
Traceback (most recent call last):
  File "/usr/lib/python3/dist-packages/urllib3/connectionpool.py", line 445, in _make_request
    six.raise_from(e, None)
  File "<string>", line 3, in raise_from
  File "/usr/lib/python3/dist-packages/urllib3/connectionpool.py", line 440, in _make_request
    httplib_response = conn.getresponse()
  File "/usr/lib/python3.9/http/client.py", line 1371, in getresponse
    response.begin()
  File "/usr/lib/python3.9/http/client.py", line 319, in begin
    version, status, reason = self._read_status()
  File "/usr/lib/python3.9/http/client.py", line 280, in _read_status
    line = str(self.fp.readline(_MAXLINE + 1), "iso-8859-1")
  File "/usr/lib/python3.9/socket.py", line 704, in readinto
    return self._sock.recv_into(b)
  File "/usr/lib/python3.9/ssl.py", line 1241, in recv_into
    return self.read(nbytes, buffer)
  File "/usr/lib/python3.9/ssl.py", line 1099, in read
    return self._sslobj.read(len, buffer)
socket.timeout: The read operation timed out

During handling of the above exception, another exception occurred:

Traceback (most recent call last):
  File "/usr/lib/python3/dist-packages/requests/adapters.py", line 439, in send
    resp = conn.urlopen(
  File "/usr/lib/python3/dist-packages/urllib3/connectionpool.py", line 755, in urlopen
    retries = retries.increment(
  File "/usr/lib/python3/dist-packages/urllib3/util/retry.py", line 532, in increment
    raise six.reraise(type(error), error, _stacktrace)
  File "/usr/lib/python3/dist-packages/six.py", line 719, in reraise
    raise value
  File "/usr/lib/python3/dist-packages/urllib3/connectionpool.py", line 699, in urlopen
    httplib_response = self._make_request(
  File "/usr/lib/python3/dist-packages/urllib3/connectionpool.py", line 447, in _make_request
    self._raise_timeout(err=e, url=url, timeout_value=read_timeout)
  File "/usr/lib/python3/dist-packages/urllib3/connectionpool.py", line 336, in _raise_timeout
    raise ReadTimeoutError(
urllib3.exceptions.ReadTimeoutError: HTTPSConnectionPool(host='api.telegram.org', port=443): Read timed out. (read timeout=10)

During handling of the above exception, another exception occurred:

Traceback (most recent call last):
  File "/home/vaskozlov/.local/lib/python3.9/site-packages/telebot/__init__.py", line 617, in infinity_polling
    self.polling(none_stop=True, timeout=timeout, long_polling_timeout=long_polling_timeout,
  File "/home/vaskozlov/.local/lib/python3.9/site-packages/telebot/__init__.py", line 664, in polling
    self.__threaded_polling(non_stop, interval, timeout, long_polling_timeout, allowed_updates)
  File "/home/vaskozlov/.local/lib/python3.9/site-packages/telebot/__init__.py", line 726, in __threaded_polling
    raise e
  File "/home/vaskozlov/.local/lib/python3.9/site-packages/telebot/__init__.py", line 685, in __threaded_polling
    polling_thread.raise_exceptions()
  File "/home/vaskozlov/.local/lib/python3.9/site-packages/telebot/util.py", line 106, in raise_exceptions
    raise self.exception_info
  File "/home/vaskozlov/.local/lib/python3.9/site-packages/telebot/util.py", line 88, in run
    task(*args, **kwargs)
  File "/home/vaskozlov/.local/lib/python3.9/site-packages/telebot/__init__.py", line 411, in __retrieve_updates
    updates = self.get_updates(offset=(self.last_update_id + 1),
  File "/home/vaskozlov/.local/lib/python3.9/site-packages/telebot/__init__.py", line 391, in get_updates
    json_updates = apihelper.get_updates(self.token, offset, limit, timeout, allowed_updates, long_polling_timeout)
  File "/home/vaskozlov/.local/lib/python3.9/site-packages/telebot/apihelper.py", line 328, in get_updates
    return _make_request(token, method_url, params=payload)
  File "/home/vaskozlov/.local/lib/python3.9/site-packages/telebot/apihelper.py", line 152, in _make_request
    result = _get_req_session().request(
  File "/usr/lib/python3/dist-packages/requests/sessions.py", line 542, in request
    resp = self.send(prep, **send_kwargs)
  File "/usr/lib/python3/dist-packages/requests/sessions.py", line 655, in send
    r = adapter.send(request, **kwargs)
  File "/usr/lib/python3/dist-packages/requests/adapters.py", line 529, in send
    raise ReadTimeout(e, request=request)
requests.exceptions.ReadTimeout: HTTPSConnectionPool(host='api.telegram.org', port=443): Read timed out. (read timeout=10)
"
2022-04-16 13:07:17,954 (__init__.py:621 MainThread) ERROR - TeleBot: "Infinity polling exception: HTTPSConnectionPool(host='api.telegram.org', port=443): Read timed out. (read timeout=10)"
2022-04-16 13:07:17,957 (__init__.py:623 MainThread) ERROR - TeleBot: "Exception traceback:
Traceback (most recent call last):
  File "/usr/lib/python3/dist-packages/urllib3/connectionpool.py", line 445, in _make_request
    six.raise_from(e, None)
  File "<string>", line 3, in raise_from
  File "/usr/lib/python3/dist-packages/urllib3/connectionpool.py", line 440, in _make_request
    httplib_response = conn.getresponse()
  File "/usr/lib/python3.9/http/client.py", line 1371, in getresponse
    response.begin()
  File "/usr/lib/python3.9/http/client.py", line 319, in begin
    version, status, reason = self._read_status()
  File "/usr/lib/python3.9/http/client.py", line 280, in _read_status
    line = str(self.fp.readline(_MAXLINE + 1), "iso-8859-1")
  File "/usr/lib/python3.9/socket.py", line 704, in readinto
    return self._sock.recv_into(b)
  File "/usr/lib/python3.9/ssl.py", line 1241, in recv_into
    return self.read(nbytes, buffer)
  File "/usr/lib/python3.9/ssl.py", line 1099, in read
    return self._sslobj.read(len, buffer)
socket.timeout: The read operation timed out

During handling of the above exception, another exception occurred:

Traceback (most recent call last):
  File "/usr/lib/python3/dist-packages/requests/adapters.py", line 439, in send
    resp = conn.urlopen(
  File "/usr/lib/python3/dist-packages/urllib3/connectionpool.py", line 755, in urlopen
    retries = retries.increment(
  File "/usr/lib/python3/dist-packages/urllib3/util/retry.py", line 532, in increment
    raise six.reraise(type(error), error, _stacktrace)
  File "/usr/lib/python3/dist-packages/six.py", line 719, in reraise
    raise value
  File "/usr/lib/python3/dist-packages/urllib3/connectionpool.py", line 699, in urlopen
    httplib_response = self._make_request(
  File "/usr/lib/python3/dist-packages/urllib3/connectionpool.py", line 447, in _make_request
    self._raise_timeout(err=e, url=url, timeout_value=read_timeout)
  File "/usr/lib/python3/dist-packages/urllib3/connectionpool.py", line 336, in _raise_timeout
    raise ReadTimeoutError(
urllib3.exceptions.ReadTimeoutError: HTTPSConnectionPool(host='api.telegram.org', port=443): Read timed out. (read timeout=10)

During handling of the above exception, another exception occurred:

Traceback (most recent call last):
  File "/home/vaskozlov/.local/lib/python3.9/site-packages/telebot/__init__.py", line 617, in infinity_polling
    self.polling(none_stop=True, timeout=timeout, long_polling_timeout=long_polling_timeout,
  File "/home/vaskozlov/.local/lib/python3.9/site-packages/telebot/__init__.py", line 664, in polling
    self.__threaded_polling(non_stop, interval, timeout, long_polling_timeout, allowed_updates)
  File "/home/vaskozlov/.local/lib/python3.9/site-packages/telebot/__init__.py", line 726, in __threaded_polling
    raise e
  File "/home/vaskozlov/.local/lib/python3.9/site-packages/telebot/__init__.py", line 685, in __threaded_polling
    polling_thread.raise_exceptions()
  File "/home/vaskozlov/.local/lib/python3.9/site-packages/telebot/util.py", line 106, in raise_exceptions
    raise self.exception_info
  File "/home/vaskozlov/.local/lib/python3.9/site-packages/telebot/util.py", line 88, in run
    task(*args, **kwargs)
  File "/home/vaskozlov/.local/lib/python3.9/site-packages/telebot/__init__.py", line 411, in __retrieve_updates
    updates = self.get_updates(offset=(self.last_update_id + 1),
  File "/home/vaskozlov/.local/lib/python3.9/site-packages/telebot/__init__.py", line 391, in get_updates
    json_updates = apihelper.get_updates(self.token, offset, limit, timeout, allowed_updates, long_polling_timeout)
  File "/home/vaskozlov/.local/lib/python3.9/site-packages/telebot/apihelper.py", line 328, in get_updates
    return _make_request(token, method_url, params=payload)
  File "/home/vaskozlov/.local/lib/python3.9/site-packages/telebot/apihelper.py", line 152, in _make_request
    result = _get_req_session().request(
  File "/usr/lib/python3/dist-packages/requests/sessions.py", line 542, in request
    resp = self.send(prep, **send_kwargs)
  File "/usr/lib/python3/dist-packages/requests/sessions.py", line 655, in send
    r = adapter.send(request, **kwargs)
  File "/usr/lib/python3/dist-packages/requests/adapters.py", line 529, in send
    raise ReadTimeout(e, request=request)
requests.exceptions.ReadTimeout: HTTPSConnectionPool(host='api.telegram.org', port=443): Read timed out. (read timeout=10)
"
2022-04-16 13:07:31,007 (__init__.py:621 MainThread) ERROR - TeleBot: "Infinity polling exception: HTTPSConnectionPool(host='api.telegram.org', port=443): Max retries exceeded with url: /bot1463835745:AAEsUMnybJNU5GFzXr_FAqRz7lY6qyEg4Mg/getUpdates?offset=914101586&timeout=5 (Caused by NewConnectionError('<urllib3.connection.HTTPSConnection object at 0xffff820805e0>: Failed to establish a new connection: [Errno 101] Network is unreachable'))"
2022-04-16 13:07:31,009 (__init__.py:623 MainThread) ERROR - TeleBot: "Exception traceback:
Traceback (most recent call last):
  File "/usr/lib/python3/dist-packages/urllib3/connection.py", line 169, in _new_conn
    conn = connection.create_connection(
  File "/usr/lib/python3/dist-packages/urllib3/util/connection.py", line 96, in create_connection
    raise err
  File "/usr/lib/python3/dist-packages/urllib3/util/connection.py", line 86, in create_connection
    sock.connect(sa)
OSError: [Errno 101] Network is unreachable

During handling of the above exception, another exception occurred:

Traceback (most recent call last):
  File "/usr/lib/python3/dist-packages/urllib3/connectionpool.py", line 699, in urlopen
    httplib_response = self._make_request(
  File "/usr/lib/python3/dist-packages/urllib3/connectionpool.py", line 382, in _make_request
    self._validate_conn(conn)
  File "/usr/lib/python3/dist-packages/urllib3/connectionpool.py", line 1012, in _validate_conn
    conn.connect()
  File "/usr/lib/python3/dist-packages/urllib3/connection.py", line 353, in connect
    conn = self._new_conn()
  File "/usr/lib/python3/dist-packages/urllib3/connection.py", line 181, in _new_conn
    raise NewConnectionError(
urllib3.exceptions.NewConnectionError: <urllib3.connection.HTTPSConnection object at 0xffff820805e0>: Failed to establish a new connection: [Errno 101] Network is unreachable

During handling of the above exception, another exception occurred:

Traceback (most recent call last):
  File "/usr/lib/python3/dist-packages/requests/adapters.py", line 439, in send
    resp = conn.urlopen(
  File "/usr/lib/python3/dist-packages/urllib3/connectionpool.py", line 755, in urlopen
    retries = retries.increment(
  File "/usr/lib/python3/dist-packages/urllib3/util/retry.py", line 574, in increment
    raise MaxRetryError(_pool, url, error or ResponseError(cause))
urllib3.exceptions.MaxRetryError: HTTPSConnectionPool(host='api.telegram.org', port=443): Max retries exceeded with url: /bot1463835745:AAEsUMnybJNU5GFzXr_FAqRz7lY6qyEg4Mg/getUpdates?offset=914101586&timeout=5 (Caused by NewConnectionError('<urllib3.connection.HTTPSConnection object at 0xffff820805e0>: Failed to establish a new connection: [Errno 101] Network is unreachable'))

During handling of the above exception, another exception occurred:

Traceback (most recent call last):
  File "/home/vaskozlov/.local/lib/python3.9/site-packages/telebot/__init__.py", line 617, in infinity_polling
    self.polling(none_stop=True, timeout=timeout, long_polling_timeout=long_polling_timeout,
  File "/home/vaskozlov/.local/lib/python3.9/site-packages/telebot/__init__.py", line 664, in polling
    self.__threaded_polling(non_stop, interval, timeout, long_polling_timeout, allowed_updates)
  File "/home/vaskozlov/.local/lib/python3.9/site-packages/telebot/__init__.py", line 726, in __threaded_polling
    raise e
  File "/home/vaskozlov/.local/lib/python3.9/site-packages/telebot/__init__.py", line 685, in __threaded_polling
    polling_thread.raise_exceptions()
  File "/home/vaskozlov/.local/lib/python3.9/site-packages/telebot/util.py", line 106, in raise_exceptions
    raise self.exception_info
  File "/home/vaskozlov/.local/lib/python3.9/site-packages/telebot/util.py", line 88, in run
    task(*args, **kwargs)
  File "/home/vaskozlov/.local/lib/python3.9/site-packages/telebot/__init__.py", line 411, in __retrieve_updates
    updates = self.get_updates(offset=(self.last_update_id + 1),
  File "/home/vaskozlov/.local/lib/python3.9/site-packages/telebot/__init__.py", line 391, in get_updates
    json_updates = apihelper.get_updates(self.token, offset, limit, timeout, allowed_updates, long_polling_timeout)
  File "/home/vaskozlov/.local/lib/python3.9/site-packages/telebot/apihelper.py", line 328, in get_updates
    return _make_request(token, method_url, params=payload)
  File "/home/vaskozlov/.local/lib/python3.9/site-packages/telebot/apihelper.py", line 152, in _make_request
    result = _get_req_session().request(
  File "/usr/lib/python3/dist-packages/requests/sessions.py", line 542, in request
    resp = self.send(prep, **send_kwargs)
  File "/usr/lib/python3/dist-packages/requests/sessions.py", line 655, in send
    r = adapter.send(request, **kwargs)
  File "/usr/lib/python3/dist-packages/requests/adapters.py", line 516, in send
    raise ConnectionError(e, request=request)
requests.exceptions.ConnectionError: HTTPSConnectionPool(host='api.telegram.org', port=443): Max retries exceeded with url: /bot1463835745:AAEsUMnybJNU5GFzXr_FAqRz7lY6qyEg4Mg/getUpdates?offset=914101586&timeout=5 (Caused by NewConnectionError('<urllib3.connection.HTTPSConnection object at 0xffff820805e0>: Failed to establish a new connection: [Errno 101] Network is unreachable'))
"
2022-04-16 18:16:16,662 (__init__.py:694 MainThread) ERROR - TeleBot: "A request to the Telegram API was unsuccessful. Error code: 502. Description: Bad Gateway"
2022-04-16 18:16:17,024 (__init__.py:694 MainThread) ERROR - TeleBot: "A request to the Telegram API was unsuccessful. Error code: 502. Description: Bad Gateway"
2022-04-16 18:16:17,619 (__init__.py:694 MainThread) ERROR - TeleBot: "A request to the Telegram API was unsuccessful. Error code: 502. Description: Bad Gateway"
2022-04-16 18:16:28,641 (__init__.py:621 MainThread) ERROR - TeleBot: "Infinity polling exception: HTTPSConnectionPool(host='api.telegram.org', port=443): Read timed out. (read timeout=10)"
2022-04-16 18:16:28,644 (__init__.py:623 MainThread) ERROR - TeleBot: "Exception traceback:
Traceback (most recent call last):
  File "/usr/lib/python3/dist-packages/urllib3/connectionpool.py", line 445, in _make_request
    six.raise_from(e, None)
  File "<string>", line 3, in raise_from
  File "/usr/lib/python3/dist-packages/urllib3/connectionpool.py", line 440, in _make_request
    httplib_response = conn.getresponse()
  File "/usr/lib/python3.9/http/client.py", line 1371, in getresponse
    response.begin()
  File "/usr/lib/python3.9/http/client.py", line 319, in begin
    version, status, reason = self._read_status()
  File "/usr/lib/python3.9/http/client.py", line 280, in _read_status
    line = str(self.fp.readline(_MAXLINE + 1), "iso-8859-1")
  File "/usr/lib/python3.9/socket.py", line 704, in readinto
    return self._sock.recv_into(b)
  File "/usr/lib/python3.9/ssl.py", line 1241, in recv_into
    return self.read(nbytes, buffer)
  File "/usr/lib/python3.9/ssl.py", line 1099, in read
    return self._sslobj.read(len, buffer)
socket.timeout: The read operation timed out

During handling of the above exception, another exception occurred:

Traceback (most recent call last):
  File "/usr/lib/python3/dist-packages/requests/adapters.py", line 439, in send
    resp = conn.urlopen(
  File "/usr/lib/python3/dist-packages/urllib3/connectionpool.py", line 755, in urlopen
    retries = retries.increment(
  File "/usr/lib/python3/dist-packages/urllib3/util/retry.py", line 532, in increment
    raise six.reraise(type(error), error, _stacktrace)
  File "/usr/lib/python3/dist-packages/six.py", line 719, in reraise
    raise value
  File "/usr/lib/python3/dist-packages/urllib3/connectionpool.py", line 699, in urlopen
    httplib_response = self._make_request(
  File "/usr/lib/python3/dist-packages/urllib3/connectionpool.py", line 447, in _make_request
    self._raise_timeout(err=e, url=url, timeout_value=read_timeout)
  File "/usr/lib/python3/dist-packages/urllib3/connectionpool.py", line 336, in _raise_timeout
    raise ReadTimeoutError(
urllib3.exceptions.ReadTimeoutError: HTTPSConnectionPool(host='api.telegram.org', port=443): Read timed out. (read timeout=10)

During handling of the above exception, another exception occurred:

Traceback (most recent call last):
  File "/home/vaskozlov/.local/lib/python3.9/site-packages/telebot/__init__.py", line 617, in infinity_polling
    self.polling(none_stop=True, timeout=timeout, long_polling_timeout=long_polling_timeout,
  File "/home/vaskozlov/.local/lib/python3.9/site-packages/telebot/__init__.py", line 664, in polling
    self.__threaded_polling(non_stop, interval, timeout, long_polling_timeout, allowed_updates)
  File "/home/vaskozlov/.local/lib/python3.9/site-packages/telebot/__init__.py", line 726, in __threaded_polling
    raise e
  File "/home/vaskozlov/.local/lib/python3.9/site-packages/telebot/__init__.py", line 685, in __threaded_polling
    polling_thread.raise_exceptions()
  File "/home/vaskozlov/.local/lib/python3.9/site-packages/telebot/util.py", line 106, in raise_exceptions
    raise self.exception_info
  File "/home/vaskozlov/.local/lib/python3.9/site-packages/telebot/util.py", line 88, in run
    task(*args, **kwargs)
  File "/home/vaskozlov/.local/lib/python3.9/site-packages/telebot/__init__.py", line 411, in __retrieve_updates
    updates = self.get_updates(offset=(self.last_update_id + 1),
  File "/home/vaskozlov/.local/lib/python3.9/site-packages/telebot/__init__.py", line 391, in get_updates
    json_updates = apihelper.get_updates(self.token, offset, limit, timeout, allowed_updates, long_polling_timeout)
  File "/home/vaskozlov/.local/lib/python3.9/site-packages/telebot/apihelper.py", line 328, in get_updates
    return _make_request(token, method_url, params=payload)
  File "/home/vaskozlov/.local/lib/python3.9/site-packages/telebot/apihelper.py", line 152, in _make_request
    result = _get_req_session().request(
  File "/usr/lib/python3/dist-packages/requests/sessions.py", line 542, in request
    resp = self.send(prep, **send_kwargs)
  File "/usr/lib/python3/dist-packages/requests/sessions.py", line 655, in send
    r = adapter.send(request, **kwargs)
  File "/usr/lib/python3/dist-packages/requests/adapters.py", line 529, in send
    raise ReadTimeout(e, request=request)
requests.exceptions.ReadTimeout: HTTPSConnectionPool(host='api.telegram.org', port=443): Read timed out. (read timeout=10)
"
2022-04-16 18:16:41,886 (__init__.py:621 MainThread) ERROR - TeleBot: "Infinity polling exception: HTTPSConnectionPool(host='api.telegram.org', port=443): Read timed out. (read timeout=10)"
2022-04-16 18:16:41,890 (__init__.py:623 MainThread) ERROR - TeleBot: "Exception traceback:
Traceback (most recent call last):
  File "/usr/lib/python3/dist-packages/urllib3/connectionpool.py", line 445, in _make_request
    six.raise_from(e, None)
  File "<string>", line 3, in raise_from
  File "/usr/lib/python3/dist-packages/urllib3/connectionpool.py", line 440, in _make_request
    httplib_response = conn.getresponse()
  File "/usr/lib/python3.9/http/client.py", line 1371, in getresponse
    response.begin()
  File "/usr/lib/python3.9/http/client.py", line 319, in begin
    version, status, reason = self._read_status()
  File "/usr/lib/python3.9/http/client.py", line 280, in _read_status
    line = str(self.fp.readline(_MAXLINE + 1), "iso-8859-1")
  File "/usr/lib/python3.9/socket.py", line 704, in readinto
    return self._sock.recv_into(b)
  File "/usr/lib/python3.9/ssl.py", line 1241, in recv_into
    return self.read(nbytes, buffer)
  File "/usr/lib/python3.9/ssl.py", line 1099, in read
    return self._sslobj.read(len, buffer)
socket.timeout: The read operation timed out

During handling of the above exception, another exception occurred:

Traceback (most recent call last):
  File "/usr/lib/python3/dist-packages/requests/adapters.py", line 439, in send
    resp = conn.urlopen(
  File "/usr/lib/python3/dist-packages/urllib3/connectionpool.py", line 755, in urlopen
    retries = retries.increment(
  File "/usr/lib/python3/dist-packages/urllib3/util/retry.py", line 532, in increment
    raise six.reraise(type(error), error, _stacktrace)
  File "/usr/lib/python3/dist-packages/six.py", line 719, in reraise
    raise value
  File "/usr/lib/python3/dist-packages/urllib3/connectionpool.py", line 699, in urlopen
    httplib_response = self._make_request(
  File "/usr/lib/python3/dist-packages/urllib3/connectionpool.py", line 447, in _make_request
    self._raise_timeout(err=e, url=url, timeout_value=read_timeout)
  File "/usr/lib/python3/dist-packages/urllib3/connectionpool.py", line 336, in _raise_timeout
    raise ReadTimeoutError(
urllib3.exceptions.ReadTimeoutError: HTTPSConnectionPool(host='api.telegram.org', port=443): Read timed out. (read timeout=10)

During handling of the above exception, another exception occurred:

Traceback (most recent call last):
  File "/home/vaskozlov/.local/lib/python3.9/site-packages/telebot/__init__.py", line 617, in infinity_polling
    self.polling(none_stop=True, timeout=timeout, long_polling_timeout=long_polling_timeout,
  File "/home/vaskozlov/.local/lib/python3.9/site-packages/telebot/__init__.py", line 664, in polling
    self.__threaded_polling(non_stop, interval, timeout, long_polling_timeout, allowed_updates)
  File "/home/vaskozlov/.local/lib/python3.9/site-packages/telebot/__init__.py", line 726, in __threaded_polling
    raise e
  File "/home/vaskozlov/.local/lib/python3.9/site-packages/telebot/__init__.py", line 685, in __threaded_polling
    polling_thread.raise_exceptions()
  File "/home/vaskozlov/.local/lib/python3.9/site-packages/telebot/util.py", line 106, in raise_exceptions
    raise self.exception_info
  File "/home/vaskozlov/.local/lib/python3.9/site-packages/telebot/util.py", line 88, in run
    task(*args, **kwargs)
  File "/home/vaskozlov/.local/lib/python3.9/site-packages/telebot/__init__.py", line 411, in __retrieve_updates
    updates = self.get_updates(offset=(self.last_update_id + 1),
  File "/home/vaskozlov/.local/lib/python3.9/site-packages/telebot/__init__.py", line 391, in get_updates
    json_updates = apihelper.get_updates(self.token, offset, limit, timeout, allowed_updates, long_polling_timeout)
  File "/home/vaskozlov/.local/lib/python3.9/site-packages/telebot/apihelper.py", line 328, in get_updates
    return _make_request(token, method_url, params=payload)
  File "/home/vaskozlov/.local/lib/python3.9/site-packages/telebot/apihelper.py", line 152, in _make_request
    result = _get_req_session().request(
  File "/usr/lib/python3/dist-packages/requests/sessions.py", line 542, in request
    resp = self.send(prep, **send_kwargs)
  File "/usr/lib/python3/dist-packages/requests/sessions.py", line 655, in send
    r = adapter.send(request, **kwargs)
  File "/usr/lib/python3/dist-packages/requests/adapters.py", line 529, in send
    raise ReadTimeout(e, request=request)
requests.exceptions.ReadTimeout: HTTPSConnectionPool(host='api.telegram.org', port=443): Read timed out. (read timeout=10)
"
